<?xml version="1.0"?>
<sdf version="1.8">
  <model name='smarty'>

    <link name='chassis'>
      <pose>-0.151427 -0 0.175 0 -0 0</pose>
      <inertial>
        <mass>1.14395</mass>
        <inertia>
          <ixx>0.126164</ixx>
          <ixy>0</ixy>
          <ixz>0</ixz>
          <iyy>0.416519</iyy>
          <iyz>0</iyz>
          <izz>0.481014</izz>
        </inertia>
      </inertial>
      <visual name='visual_chassis'>
        <geometry>
          <box>
            <size>2.01142 1 0.568726</size>
          </box>
        </geometry>
        <material>
          <ambient>0.5 0.5 1.0 1</ambient>
          <diffuse>0.5 0.5 1.0 1</diffuse>
          <specular>0.0 0.0 1.0 1</specular>
        </material>
      </visual>
      <collision name='collision_chassis'>
        <geometry>
          <box>
            <size>2.01142 1 0.568726</size>
          </box>
        </geometry>
      </collision>
    </link>

    <link name='front_left_wheel'>
      <pose>0.554283 0.625029 -0.025 -1.5707 0 0</pose>
      <inertial>
        <mass>2</mass>
        <inertia>
          <ixx>0.145833</ixx>
          <ixy>0</ixy>
          <ixz>0</ixz>
          <iyy>0.145833</iyy>
          <iyz>0</iyz>
          <izz>0.125</izz>
        </inertia>
      </inertial>
      <visual name='visual_front_left_wheel'>
        <geometry>
          <cylinder>
            <length>0.15</length>
            <radius>0.3</radius>
          </cylinder>
        </geometry>
        <material>
          <ambient>0.2 0.2 0.2 1</ambient>
          <diffuse>0.2 0.2 0.2 1</diffuse>
          <specular>0.2 0.2 0.2 1</specular>
        </material>
      </visual>
      <collision name='collision_front_left_wheel'>
        <geometry>
          <cylinder>
            <length>0.15</length>
            <radius>0.3</radius>
          </cylinder>
        </geometry>
        <surface>
          <friction>
            <ode>
              <mu>0.5</mu>
              <mu2>1.0</mu2>
              <fdir1>0 0 1</fdir1>
            </ode>
            <bullet>
              <friction>0.5</friction>
              <friction2>1</friction2>
              <rolling_friction>0.1</rolling_friction>
            </bullet>
          </friction>
        </surface>
      </collision>
    </link>

    <link name='rear_left_wheel'>
      <pose>-0.957138 0.625029 -0.025 -1.5707 0 0</pose>
      <inertial>
        <mass>2</mass>
        <inertia>
          <ixx>0.145833</ixx>
          <ixy>0</ixy>
          <ixz>0</ixz>
          <iyy>0.145833</iyy>
          <iyz>0</iyz>
          <izz>0.125</izz>
        </inertia>
      </inertial>
      <visual name='visual_rear_left_wheel'>
        <geometry>
          <cylinder>
            <length>0.15</length>
            <radius>0.3</radius>
          </cylinder>
        </geometry>
        <material>
          <ambient>0.2 0.2 0.2 1</ambient>
          <diffuse>0.2 0.2 0.2 1</diffuse>
          <specular>0.2 0.2 0.2 1</specular>
        </material>
      </visual>
      <collision name='collision_rear_left_wheel'>
        <geometry>
          <cylinder>
            <length>0.15</length>
            <radius>0.3</radius>
          </cylinder>
        </geometry>
        <surface>
          <friction>
            <ode>
              <mu>0.5</mu>
              <mu2>1.0</mu2>
              <fdir1>0 0 1</fdir1>
            </ode>
            <bullet>
              <friction>0.5</friction>
              <friction2>1</friction2>
              <rolling_friction>0.5</rolling_friction>
            </bullet>
          </friction>
        </surface>
      </collision>
    </link>

    <link name='front_right_wheel'>
      <pose>0.554282 -0.625029 -0.025 -1.5707 0 0</pose>
      <inertial>
        <mass>2</mass>
        <inertia>
          <ixx>0.145833</ixx>
          <ixy>0</ixy>
          <ixz>0</ixz>
          <iyy>0.145833</iyy>
          <iyz>0</iyz>
          <izz>0.125</izz>
        </inertia>
      </inertial>
      <visual name='visual_front_right_wheel'>
        <geometry>
          <cylinder>
            <length>0.15</length>
            <radius>0.3</radius>
          </cylinder>
        </geometry>
        <material>
          <ambient>0.2 0.2 0.2 1</ambient>
          <diffuse>0.2 0.2 0.2 1</diffuse>
          <specular>0.2 0.2 0.2 1</specular>
        </material>
      </visual>
      <collision name='collision_front_right_wheel'>
        <geometry>
          <cylinder>
            <length>0.15</length>
            <radius>0.3</radius>
          </cylinder>
        </geometry>
        <surface>
          <friction>
            <ode>
              <mu>0.5</mu>
              <mu2>1.0</mu2>
              <fdir1>0 0 1</fdir1>
            </ode>
            <bullet>
              <friction>0.5</friction>
              <friction2>1</friction2>
              <rolling_friction>0.1</rolling_friction>
            </bullet>
          </friction>
        </surface>
      </collision>
    </link>

    <link name='rear_right_wheel'>
      <pose>-0.957138 -0.625029 -0.025 -1.5707 0 0</pose>
      <inertial>
        <mass>2</mass>
        <inertia>
          <ixx>0.145833</ixx>
          <ixy>0</ixy>
          <ixz>0</ixz>
          <iyy>0.145833</iyy>
          <iyz>0</iyz>
          <izz>0.125</izz>
        </inertia>
      </inertial>
      <visual name='visual_rear_right_wheel'>
        <geometry>
          <cylinder>
            <length>0.15</length>
            <radius>0.3</radius>
          </cylinder>
        </geometry>
        <material>
          <ambient>0.2 0.2 0.2 1</ambient>
          <diffuse>0.2 0.2 0.2 1</diffuse>
          <specular>0.2 0.2 0.2 1</specular>
        </material>
      </visual>
      <collision name='collision_rear_right_wheel'>
        <geometry>
          <cylinder>
            <length>0.15</length>
            <radius>0.3</radius>
          </cylinder>
        </geometry>
        <surface>
          <friction>
            <ode>
              <mu>0.5</mu>
              <mu2>1.0</mu2>
              <fdir1>0 0 1</fdir1>
            </ode>
            <bullet>
              <friction>0.5</friction>
              <friction2>1</friction2>
              <rolling_friction>0.5</rolling_friction>
            </bullet>
          </friction>
        </surface>
      </collision>
    </link>

    <link name="front_left_wheel_steering_link">
      <pose>0.554283 0.5 0.02 0 0 0</pose>
      <inertial>
        <mass>0.5</mass>
        <inertia>
          <ixx>0.0153</ixx>
          <iyy>0.025</iyy>
          <izz>0.0153</izz>
        </inertia>
      </inertial>
      <visual name="steering_link_visual">
        <pose>0 0 0 0 0 0</pose>
        <geometry>
          <cylinder>
            <length>0.1</length>
            <radius>0.03</radius>
          </cylinder>
        </geometry>
        <material>
          <ambient>1 1 1</ambient>
          <diffuse>1 1 1</diffuse>
        </material>
      </visual>
    </link>

    <link name="front_right_wheel_steering_link">
      <pose>0.554283 -0.5 0.02 0 0 0</pose>
      <inertial>
        <mass>0.5</mass>
        <inertia>
          <ixx>0.0153</ixx>
          <iyy>0.025</iyy>
          <izz>0.0153</izz>
        </inertia>
      </inertial>
      <visual name="steering_link_visual">
        <pose>0 0 0 0 0 0</pose>
        <geometry>
          <cylinder>
            <length>0.1</length>
            <radius>0.03</radius>
          </cylinder>
        </geometry>
        <material>
          <ambient>1 1 1</ambient>
          <diffuse>1 1 1</diffuse>
        </material>
      </visual>
    </link>

    <joint name="front_left_wheel_steering_joint" type="revolute">
      <parent>chassis</parent>
      <child>front_left_wheel_steering_link</child>
      <axis>
        <xyz>0 0 1</xyz>
        <limit>
          <lower>-0.6</lower>
          <upper>+0.6</upper>
          <velocity>1.0</velocity>
          <effort>25</effort>
        </limit>
      </axis>
    </joint>

    <joint name="front_right_wheel_steering_joint" type="revolute">
      <parent>chassis</parent>
      <child>front_right_wheel_steering_link</child>
      <axis>
        <xyz>0 0 1</xyz>
        <limit>
          <lower>-0.6</lower>
          <upper>+0.6</upper>
          <velocity>1.0</velocity>
          <effort>25</effort>
        </limit>
      </axis>
    </joint>

    <joint name='front_left_wheel_joint' type='revolute'>
      <parent>front_left_wheel_steering_link</parent>
      <child>front_left_wheel</child>
      <axis>
        <xyz>0 0 1</xyz>
        <limit>
          <lower>-1.79769e+308</lower>
          <upper>1.79769e+308</upper>
        </limit>
      </axis>
    </joint>

    <joint name='front_right_wheel_joint' type='revolute'>
      <parent>front_right_wheel_steering_link</parent>
      <child>front_right_wheel</child>
      <axis>
        <xyz>0 0 1</xyz>
        <limit>
          <lower>-1.79769e+308</lower>
          <upper>1.79769e+308</upper>
        </limit>
      </axis>
    </joint>

    <joint name='rear_left_wheel_joint' type='revolute'>
      <parent>chassis</parent>
      <child>rear_left_wheel</child>
      <axis>
        <xyz>0 0 1</xyz>
        <limit>
          <lower>-1.79769e+308</lower>
          <upper>1.79769e+308</upper>
        </limit>
      </axis>
    </joint>

    <joint name='rear_right_wheel_joint' type='revolute'>
      <parent>chassis</parent>
      <child>rear_right_wheel</child>
      <axis>
        <xyz>0 0 1</xyz>
        <limit>
          <lower>-1.79769e+308</lower>
          <upper>1.79769e+308</upper>
        </limit>
      </axis>
    </joint>

    <link name="camera_link">
      <pose>-0.4 0 0.75 0 0 0</pose>
      <inertial>
        <mass>0.1</mass>
        <inertia>
          <ixx>0.000166667</ixx>
          <iyy>0.000166667</iyy>
          <izz>0.000166667</izz>
        </inertia>
      </inertial>
      <collision name="collision_camera">
        <geometry>
          <box>
            <size>0.1 0.1 0.1</size>
          </box>
        </geometry>
      </collision>
      <visual name="visual_camera">
        <geometry>
          <box>
            <size>0.1 0.1 0.1</size>
          </box>
        </geometry>
      </visual>
      <sensor name="camera" type="camera">
        <camera>
          <horizontal_fov>1.047</horizontal_fov>
          <image>
            <width>320</width>
            <height>240</height>
          </image>
          <clip>
            <near>0.1</near>
            <far>100</far>
          </clip>
        </camera>
        <always_on>1</always_on>
        <update_rate>30</update_rate>
        <visualize>true</visualize>
        <topic>camera</topic>
      </sensor>
    </link>

    <joint name='camera_joint' type='fixed'>
      <parent>chassis</parent>
      <child>camera_link</child>
    </joint>

  </model>
</sdf>
